<?xml version="1.0" encoding="utf-8"?>
<!-- 这是一个G1的URDF描述文件 -->
<robot name="g1_description">
  <!-- 基座link：机器人的底盘 -->
  <link name="base_link">
    <inertial>
      <origin xyz="-0.0134486971267798 0.00152103941353612 -0.0320076754329413" rpy="0 0 0"/>
      <mass value="23.2085382238952"/>  <!-- 底盘质量约23.2kg -->
      <inertia
        ixx="0.386955641760608" ixy="0.000135417314593726" ixz="0.00669301645720665"
        iyy="0.366800407621218" iyz="0.000105713634260505" izz="0.546852919828475"/>
    </inertial>

    <visual>
      <origin xyz="0 0 0" rpy="0 0 0"/>
      <geometry>
        <mesh filename="package://g1_description/meshes/base_link.STL"/>
      </geometry>
      <material name="">
        <color rgba="0.752941176470588 0.752941176470588 0.752941176470588 1"/>  <!-- 灰色 -->
      </material>
    </visual>

    <collision>
      <origin xyz="0 0 0" rpy="0 0 0"/>
      <geometry>
        <mesh filename="package://g1_description/meshes/base_link.STL"/>
      </geometry>
    </collision>
  </link>

  <!-- 升降机构link：控制整体高度的部分 -->
  <link name="link-up-down_body">
    <inertial>
      <origin xyz="0.0338351537064605 -0.00248044044451858 0.000838431095422365" rpy="0 0 0"/>
      <mass value="3.26275452360108"/>
      <inertia
        ixx="0.0128301877197417" ixy="8.24967996575627E-06" ixz="1.38254543337324E-05"
        iyy="0.006104110250297" iyz="-7.99392548994692E-06" izz="0.0111721084996867"/>
    </inertial>

    <visual>
      <origin xyz="0 0 0" rpy="0 0 0"/>
      <geometry>
        <mesh filename="package://g1_description/meshes/link-up-down_body.STL"/>
      </geometry>
      <material name="">
        <color rgba="0.752941176470588 0.752941176470588 0.752941176470588 1"/>
      </material>
    </visual>

    <collision>
      <origin xyz="0 0 0" rpy="0 0 0"/>
      <geometry>
        <mesh filename="package://g1_description/meshes/link-up-down_body.STL"/>
      </geometry>
    </collision>
  </link>

  <!-- 升降关节：控制机器人整体高度，可上升30cm -->
  <joint name="joint_lift_body" type="prismatic">
    <origin xyz="0 0 0.3485" rpy="0 0 0"/>  <!-- 从底盘上方34.85cm处开始 -->
    <parent link="base_link"/>
    <child link="link-up-down_body"/>
    <axis xyz="0 0 1"/>                      <!-- 沿Z轴方向运动 -->
    <limit lower="0" upper="0.555" effort="100" velocity="0.1"/>  <!-- 升降范围0-55.5cm -->
  </joint>

  <!-- 身体俯仰link：可前后倾斜的躯干部分 -->
  <link name="link-pitch_body">
    <inertial>
      <origin xyz="0.193733558855111 -0.000484180179482319 -0.00124011422952511" rpy="0 0 0"/>
      <mass value="7.53199207979272"/>
      <inertia
        ixx="0.016546682835947" ixy="0.000274441382484697" ixz="0.00102757387076422"
        iyy="0.0445441227006132" iyz="-0.000236858278708531" izz="0.0402036337794082"/>
    </inertial>

    <visual>
      <origin xyz="0 0 0" rpy="3.14159 0 0"/>
      <geometry>
        <mesh filename="package://g1_description/meshes/link-pitch_body.STL"/>
      </geometry>
      <material name="">
        <color rgba="0.752941176470588 0.752941176470588 0.752941176470588 1"/>
      </material>
    </visual>

    <collision>
      <origin xyz="0 0 0" rpy="3.14159 0 0"/>
      <geometry>
        <mesh filename="package://g1_description/meshes/link-pitch_body.STL"/>
      </geometry>
    </collision>
  </link>

  <!-- 身体俯仰关节：控制机器人俯仰，可俯仰45度 -->
  <joint name="joint_body_pitch" type="revolute">
    <origin xyz="0.131 0 0" rpy="1.5708 -1.5708 0"/>  <!-- 从升降机构前方13.1cm处 -->
    <parent link="link-up-down_body"/>
    <child link="link-pitch_body"/>
    <axis xyz="0 0 -1"/>                              <!-- 绕Z轴负方向旋转 -->
    <limit lower="0" upper="1.5708" effort="100" velocity="0.5"/>  <!-- 0-90度俯仰 -->
  </joint>

  <!-- 头部偏航link：可左右转动的头部 -->
  <link name="link-yaw_head">
    <inertial>
      <origin xyz="0.0446068140025754 0.00241753143645124 0.0528373754603559" rpy="0 0 0"/>
      <mass value="0.414342871921048"/>
      <inertia
        ixx="0.000158695728344024" ixy="-1.04590928109554E-06" ixz="-6.58530903139189E-06"
        iyy="0.000117742864399469" iyz="-2.65011299996072E-06" izz="0.000170947040827065"/>
    </inertial>

    <visual>
      <origin xyz="0 0 0" rpy="0 0 3.14159"/>
      <geometry>
        <mesh filename="package://g1_description/meshes/link-yaw_head.STL"/>
      </geometry>
      <material name="">
        <color rgba="0.752941176470588 0.752941176470588 0.752941176470588 1"/>
      </material>
    </visual>

    <collision>
      <origin xyz="0 0 0" rpy="0 0 3.14159"/>
      <geometry>
        <mesh filename="package://g1_description/meshes/link-yaw_head.STL"/>
      </geometry>
    </collision>
  </link>

  <!-- 头部偏航关节：控制头部左右转动，每边90度 -->
  <joint name="joint_head_yaw" type="revolute">
    <origin xyz="0.441 0 0" rpy="1.5708 0 1.5708"/>  <!-- 从躯干前方44.1cm处 -->
    <parent link="link-pitch_body"/>
    <child link="link-yaw_head"/>
    <axis xyz="0 0 1"/>                              <!-- 绕Z轴旋转 -->
    <limit lower="-1.5708" upper="1.5708" effort="50" velocity="1.0"/>  <!-- 左右各90度 -->
  </joint>

  <!-- 头部俯仰link：可上下点头的部分 -->
  <link name="link-pitch_head">
    <inertial>
      <origin xyz="0.0257009265816389 0.0316254080188787 -3.77390122592164E-05" rpy="0 0 0"/>
      <mass value="0.707063977171202"/>
      <inertia
        ixx="0.00205409595373573" ixy="0.000347730118005016" ixz="-2.13857752451204E-06"
        iyy="0.00200357281313449" iyz="5.16150600423908E-08" izz="0.00184999028444405"/>
    </inertial>

    <visual>
      <origin xyz="0 0 0" rpy="0 3.14159 0"/>
      <geometry>
        <mesh filename="package://g1_description/meshes/link-pitch_head.STL"/>
      </geometry>
      <material name="">
        <color rgba="0.752941176470588 0.752941176470588 0.752941176470588 1"/>
      </material>
    </visual>

    <collision>
      <origin xyz="0 0 0" rpy="0 3.14159 0"/>
      <geometry>
        <mesh filename="package://g1_description/meshes/link-pitch_head.STL"/>
      </geometry>
    </collision>
  </link>

  <!-- 头部俯仰关节：控制头部上下点头，每边45度 -->
  <joint name="joint_head_pitch" type="revolute">
    <origin xyz="-0.050238 0 0.060065" rpy="1.5708 0 0"/>
    <parent link="link-yaw_head"/>
    <child link="link-pitch_head"/>
    <axis xyz="0 0 1"/>
    <limit lower="-0.34888" upper="0.5233" effort="50" velocity="1.0"/>  <!-- 向上20度 向下30度 -->
  </joint>

  <!-- 机械臂link：固定在躯干上的机械臂 -->
  <link name="link-arm"/>

  <!-- 机械臂固定关节：将机械臂固定在躯干上 -->
  <joint name="joint_arm_mount" type="fixed">
    <origin xyz="0.305 0 0" rpy="-1.5708 0 -1.5708"/>  <!-- 从躯干前方30.5cm处固定 -->
    <parent link="link-pitch_body"/>
    <child link="link-arm"/>
    <axis xyz="0 0 1"/>
  </joint>

  <!-- 左臂固定关节：将左臂固定在机器人躯干上 -->
  <joint name="joint_left_arm_mount" type="fixed">
    <origin xyz="0 0.025 0" rpy="-1.5708 0 0"/>  <!-- 从link-arm向左偏移2.5cm -->
    <parent link="link-arm"/>
    <child link="base_link_l"/>
  </joint>

  <!-- 右臂固定关节：将右臂固定在机器人躯干上 -->
  <joint name="joint_right_arm_mount" type="fixed">
    <origin xyz="0 -0.025 0" rpy="1.5708 -3.14159 0"/>  <!-- 从link-arm向右偏移2.5cm -->
    <parent link="link-arm"/>
    <child link="base_link_r"/>
  </joint>

  <!-- 左臂的所有link和joint定义 -->
  <link
    name="base_link_l">
    <inertial>
      <origin
        xyz="-0.00020641 0.00057488 0.032296"
        rpy="0 0 0" />
      <mass
        value="0.37595" />
      <inertia
        ixx="0.00024335"
        ixy="1.2188E-06"
        ixz="-2.4281E-06"
        iyy="0.00024039"
        iyz="6.6932E-06"
        izz="0.00032195" />
    </inertial>
    <visual>
      <origin
        xyz="0 0 0"
        rpy="0 0 0" />
      <geometry>
        <mesh
          filename="package://g1_description/meshes/base_link_l.STL" />
      </geometry>
      <material
        name="">
        <color
          rgba="0.75294 0.75294 0.75294 1" />
      </material>
    </visual>
    <collision>
      <origin
        xyz="0 0 0"
        rpy="0 0 0" />
      <geometry>
        <mesh
          filename="package://g1_description/meshes/base_link_l.STL" />
      </geometry>
    </collision>
  </link>
  <link
    name="Link1_l">
    <inertial>
      <origin
        xyz="-0.0012655 -0.00043778 -0.018388"
        rpy="0 0 0" />
      <mass
        value="0.4936" />
      <inertia
        ixx="0.00075396"
        ixy="6.6935E-06"
        ixz="6.1141E-06"
        iyy="0.00065755"
        iyz="1.2196E-06"
        izz="0.00031848" />
    </inertial>
    <visual>
      <origin
        xyz="0 0 0"
        rpy="0 0 0" />
      <geometry>
        <mesh
          filename="package://g1_description/meshes/Link1_l.STL" />
      </geometry>
      <material
        name="">
        <color
          rgba="0.75294 0.75294 0.75294 1" />
      </material>
    </visual>
    <collision>
      <origin
        xyz="0 0 0"
        rpy="0 0 0" />
      <geometry>
        <mesh
          filename="package://g1_description/meshes/Link1_l.STL" />
      </geometry>
    </collision>
  </link>
  <joint
    name="Joint1_l"
    type="revolute">
    <origin
      xyz="0 0 0.1859"
      rpy="0 0 0" />
    <parent
      link="base_link_l" />
    <child
      link="Link1_l" />
    <axis
      xyz="0 0 1" />
    <limit
      lower="-3.14"
      upper="3.14"
      effort="60"
      velocity="3.14" />
  </joint>
  <link
    name="Link2_l">
    <inertial>
      <origin
        xyz="5.3037E-05 -0.078258 0.0047084"
        rpy="0 0 0" />
      <mass
        value="0.46245" />
      <inertia
        ixx="0.00065719"
        ixy="3.7112E-07"
        ixz="-3.6668E-06"
        iyy="0.00043459"
        iyz="-2.517E-05"
        izz="0.00072571" />
    </inertial>
    <visual>
      <origin
        xyz="0 0 0"
        rpy="0 0 0" />
      <geometry>
        <mesh
          filename="package://g1_description/meshes/Link2_l.STL" />
      </geometry>
      <material
        name="">
        <color
          rgba="0.75294 0.75294 0.75294 1" />
      </material>
    </visual>
    <collision>
      <origin
        xyz="0 0 0"
        rpy="0 0 0" />
      <geometry>
        <mesh
          filename="package://g1_description/meshes/Link2_l.STL" />
      </geometry>
    </collision>
  </link>
  <joint
    name="Joint2_l"
    type="revolute">
    <origin
      xyz="0 0 0"
      rpy="-1.5708 0 1.5708" />
    <parent
      link="Link1_l" />
    <child
      link="Link2_l" />
    <axis
      xyz="0 0 1" />
    <limit
      lower="-2.09"
      upper="2.09"
      effort="60"
      velocity="3.14" />
  </joint>
  <link
    name="Link3_l">
    <inertial>
      <origin
        xyz="-0.0012032 0.0008714 -0.055265"
        rpy="0 0 0" />
      <mass
        value="0.50026" />
      <inertia
        ixx="0.0013016"
        ixy="3.1401E-06"
        ixz="1.4255E-05"
        iyy="0.001427"
        iyz="2.4361E-05"
        izz="0.00033587" />
    </inertial>
    <visual>
      <origin
        xyz="0 0 0"
        rpy="0 0 0" />
      <geometry>
        <mesh
          filename="package://g1_description/meshes/Link3_l.STL" />
      </geometry>
      <material
        name="">
        <color
          rgba="0.75294 0.75294 0.75294 1" />
      </material>
    </visual>
    <collision>
      <origin
        xyz="0 0 0"
        rpy="0 0 0" />
      <geometry>
        <mesh
          filename="package://g1_description/meshes/Link3_l.STL" />
      </geometry>
    </collision>
  </link>
  <joint
    name="Joint3_l"
    type="revolute">
    <origin
      xyz="0 -0.305 0"
      rpy="1.5708 1.5708 0" />
    <parent
      link="Link2_l" />
    <child
      link="Link3_l" />
    <axis
      xyz="0 0 1" />
    <limit
      lower="-3.14"
      upper="3.14"
      effort="60"
      velocity="3.14" />
  </joint>
  <link
    name="Link4_l">
    <inertial>
      <origin
        xyz="3.7035E-05 -0.06248 0.0025377"
        rpy="0 0 0" />
      <mass
        value="0.27473" />
      <inertia
        ixx="0.00029284"
        ixy="4.6615E-07"
        ixz="6.2359E-08"
        iyy="0.00018853"
        iyz="-1.1062E-06"
        izz="0.00031238" />
    </inertial>
    <visual>
      <origin
        xyz="0 0 0"
        rpy="0 0 0" />
      <geometry>
        <mesh
          filename="package://g1_description/meshes/Link4_l.STL" />
      </geometry>
      <material
        name="">
        <color
          rgba="0.75294 0.75294 0.75294 1" />
      </material>
    </visual>
    <collision>
      <origin
        xyz="0 0 0"
        rpy="0 0 0" />
      <geometry>
        <mesh
          filename="package://g1_description/meshes/Link4_l.STL" />
      </geometry>
    </collision>
  </link>
  <joint
    name="Joint4_l"
    type="revolute">
    <origin
      xyz="0 0 0"
      rpy="-1.5708 0 -3.1416" />
    <parent
      link="Link3_l" />
    <child
      link="Link4_l" />
    <axis
      xyz="0 0 1" />
    <limit
      lower="-1.48"
      upper="1.48"
      effort="60"
      velocity="3.14" />
  </joint>
  <link
    name="Link5_l">
    <inertial>
      <origin
        xyz="-7.9404E-07 -0.00023094 -0.024143"
        rpy="0 0 0" />
      <mass
        value="0.25139" />
      <inertia
        ixx="0.00023516"
        ixy="-1.3496E-09"
        ixz="-2.0314E-08"
        iyy="0.00028808"
        iyz="-1.2106E-05"
        izz="0.00013069" />
    </inertial>
    <visual>
      <origin
        xyz="0 0 0"
        rpy="0 0 0" />
      <geometry>
        <mesh
          filename="package://g1_description/meshes/Link5_l.STL" />
      </geometry>
      <material
        name="">
        <color
          rgba="0.75294 0.75294 0.75294 1" />
      </material>
    </visual>
    <collision>
      <origin
        xyz="0 0 0"
        rpy="0 0 0" />
      <geometry>
        <mesh
          filename="package://g1_description/meshes/Link5_l.STL" />
      </geometry>
    </collision>
  </link>
  <joint
    name="Joint5_l"
    type="revolute">
    <origin
      xyz="0 -0.1975 0"
      rpy="-1.5708 0 3.1416" />
    <parent
      link="Link4_l" />
    <child
      link="Link5_l" />
    <axis
      xyz="0 0 1" />
    <limit
      lower="-3.14"
      upper="3.14"
      effort="30"
      velocity="3.14" />
  </joint>
  <link
    name="Link6_l">
    <inertial>
      <origin
        xyz="1.769E-06 -0.086692 0.0025571"
        rpy="0 0 0" />
      <mass
        value="0.26634" />
      <inertia
        ixx="0.00031434"
        ixy="-2.9254E-09"
        ixz="1.0017E-07"
        iyy="0.00014464"
        iyz="-2.0329E-05"
        izz="0.0003245" />
    </inertial>
    <visual>
      <origin
        xyz="0 0 0"
        rpy="0 0 0" />
      <geometry>
        <mesh
          filename="package://g1_description/meshes/Link6_l.STL" />
      </geometry>
      <material
        name="">
        <color
          rgba="0.75294 0.75294 0.75294 1" />
      </material>
    </visual>
    <collision>
      <origin
        xyz="0 0 0"
        rpy="0 0 0" />
      <geometry>
        <mesh
          filename="package://g1_description/meshes/Link6_l.STL" />
      </geometry>
    </collision>
  </link>
  <joint
    name="Joint6_l"
    type="revolute">
    <origin
      xyz="0 0 0"
      rpy="-1.5708 0 0" />
    <parent
      link="Link5_l" />
    <child
      link="Link6_l" />
    <axis
      xyz="0 0 1" />
    <limit
      lower="-1.74"
      upper="1.74"
      effort="30"
      velocity="3.14" />
  </joint>
  <link
    name="Link7_l">
    <inertial>
      <origin
        xyz="-7.5113E-05 -0.00024521 -0.016705"
        rpy="0 0 0" />
      <mass
        value="0.06158" />
      <inertia
        ixx="1.8407E-05"
        ixy="3.4796E-08"
        ixz="-3.2424E-09"
        iyy="1.818E-05"
        iyz="1.1327E-07"
        izz="2.8547E-05" />
    </inertial>
    <visual>
      <origin
        xyz="0 0 0"
        rpy="0 0 0" />
      <geometry>
        <mesh
          filename="package://g1_description/meshes/Link7_l.STL" />
      </geometry>
      <material
        name="">
        <color
          rgba="0.75294 0.75294 0.75294 1" />
      </material>
    </visual>
    <collision>
      <origin
        xyz="0 0 0"
        rpy="0 0 0" />
      <geometry>
        <mesh
          filename="package://g1_description/meshes/Link7_l.STL" />
      </geometry>
    </collision>
  </link>
  <joint
    name="Joint7_l"
    type="revolute">
    <origin
      xyz="0 -0.1805 0"
      rpy="1.5708 0 0" />
    <parent
      link="Link6_l" />
    <child
      link="Link7_l" />
    <axis
      xyz="0 0 1" />
    <limit
      lower="-3.14"
      upper="3.14"
      effort="30"
      velocity="3.14" />
  </joint>
  <link
    name="Link_hand_l">
    <inertial>
      <origin
        xyz="0.0036691 0.0082806 0.059221"
        rpy="0 0 0" />
      <mass
        value="0.070229" />
      <inertia
        ixx="5.5259E-05"
        ixy="-8.7205E-06"
        ixz="-7.9434E-06"
        iyy="6.2355E-05"
        iyz="-1.345E-05"
        izz="4.4874E-05" />
    </inertial>
    <visual>
      <origin
        xyz="0 0 0"
        rpy="0 0 0" />
      <geometry>
        <mesh
          filename="package://g1_description/meshes/Link_hand_l.STL" />
      </geometry>
      <material
        name="">
        <color
          rgba="0.75294 0.75294 0.75294 1" />
      </material>
    </visual>
    <collision>
      <origin
        xyz="0 0 0"
        rpy="0 0 0" />
      <geometry>
        <mesh
          filename="package://g1_description/meshes/Link_hand_l.STL" />
      </geometry>
    </collision>
  </link>
  <joint
    name="Joint_hand_l"
    type="fixed">
    <origin
      xyz="0 0 0"
      rpy="0 0 -0.5236" /> <!-- 30度 -->
    <parent
      link="Link7_l" />
    <child
      link="Link_hand_l" />
    <axis
      xyz="0 0 0" />
  </joint>

  <!-- 右臂的所有link和joint定义 -->
  <link
    name="base_link_r">
    <inertial>
      <origin
        xyz="0.00020641 -0.00057488 0.034396"
        rpy="0 0 0" />
      <mass
        value="0.37595" />
      <inertia
        ixx="0.00024335"
        ixy="1.2188E-06"
        ixz="2.4281E-06"
        iyy="0.00024039"
        iyz="-6.6932E-06"
        izz="0.00032195" />
    </inertial>
    <visual>
      <origin
        xyz="0 0 0"
        rpy="0 0 0" />
      <geometry>
        <mesh
          filename="package://g1_description/meshes/base_link_r.STL" />
      </geometry>
      <material
        name="">
        <color
          rgba="0.75294 0.75294 0.75294 1" />
      </material>
    </visual>
    <collision>
      <origin
        xyz="0 0 0"
        rpy="0 0 0" />
      <geometry>
        <mesh
          filename="package://g1_description/meshes/base_link_r.STL" />
      </geometry>
    </collision>
  </link>
  <link
    name="Link1_r">
    <inertial>
      <origin
        xyz="0.0012679 -0.0001581 -0.018109"
        rpy="0 0 0" />
      <mass
        value="0.4936" />
      <inertia
        ixx="0.00075396"
        ixy="-2.4144E-06"
        ixz="-1.8364E-06"
        iyy="0.0006605"
        iyz="1.2174E-06"
        izz="0.00031553" />
    </inertial>
    <visual>
      <origin
        xyz="0 0 0"
        rpy="0 0 0" />
      <geometry>
        <mesh
          filename="package://g1_description/meshes/Link1_r.STL" />
      </geometry>
      <material
        name="">
        <color
          rgba="0.75294 0.75294 0.75294 1" />
      </material>
    </visual>
    <collision>
      <origin
        xyz="0 0 0"
        rpy="0 0 0" />
      <geometry>
        <mesh
          filename="package://g1_description/meshes/Link1_r.STL" />
      </geometry>
    </collision>
  </link>
  <joint
    name="Joint1_r"
    type="revolute">
    <origin
      xyz="0 0 0.188"
      rpy="0 0 0" />
    <parent
      link="base_link_r" />
    <child
      link="Link1_r" />
    <axis
      xyz="0 0 1" />
    <limit
      lower="-3.14"
      upper="3.14"
      effort="60"
      velocity="3.14" />
  </joint>
  <link
    name="Link2_r">
    <inertial>
      <origin
        xyz="-0.00044207 -0.082298 0.00019486"
        rpy="0 0 0" />
      <mass
        value="0.41662" />
      <inertia
        ixx="0.00054592"
        ixy="4.7265E-06"
        ixz="2.4946E-06"
        iyy="0.00039507"
        iyz="-2.0629E-05"
        izz="0.00057791" />
    </inertial>
    <visual>
      <origin
        xyz="0 0 0"
        rpy="0 0 0" />
      <geometry>
        <mesh
          filename="package://g1_description/meshes/Link2_r.STL" />
      </geometry>
      <material
        name="">
        <color
          rgba="0.75294 0.75294 0.75294 1" />
      </material>
    </visual>
    <collision>
      <origin
        xyz="0 0 0"
        rpy="0 0 0" />
      <geometry>
        <mesh
          filename="package://g1_description/meshes/Link2_r.STL" />
      </geometry>
    </collision>
  </link>
  <joint
    name="Joint2_r"
    type="revolute">
    <origin
      xyz="0 0 0"
      rpy="-1.5708 0 -1.5708" />
    <parent
      link="Link1_r" />
    <child
      link="Link2_r" />
    <axis
      xyz="0 0 1" />
    <limit
      lower="-2.09"
      upper="2.09"
      effort="60"
      velocity="3.14" />
  </joint>
  <link
    name="Link3_r">
    <inertial>
      <origin
        xyz="0.0010558 4.4416E-05 -0.056128"
        rpy="0 0 0" />
      <mass
        value="0.49413" />
      <inertia
        ixx="0.0013405"
        ixy="-6.8527E-07"
        ixz="-1.3381E-05"
        iyy="0.00142"
        iyz="2.8511E-05"
        izz="0.00037605" />
    </inertial>
    <visual>
      <origin
        xyz="0 0 0"
        rpy="0 0 0" />
      <geometry>
        <mesh
          filename="package://g1_description/meshes/Link3_r.STL" />
      </geometry>
      <material
        name="">
        <color
          rgba="0.75294 0.75294 0.75294 1" />
      </material>
    </visual>
    <collision>
      <origin
        xyz="0 0 0"
        rpy="0 0 0" />
      <geometry>
        <mesh
          filename="package://g1_description/meshes/Link3_r.STL" />
      </geometry>
    </collision>
  </link>
  <joint
    name="Joint3_r"
    type="revolute">
    <origin
      xyz="0 -0.305 0"
      rpy="1.5708 -1.5708 0" />
    <parent
      link="Link2_r" />
    <child
      link="Link3_r" />
    <axis
      xyz="0 0 1" />
    <limit
      lower="-3.14"
      upper="3.14"
      effort="60"
      velocity="3.14" />
  </joint>
  <link
    name="Link4_r">
    <inertial>
      <origin
        xyz="2.4212E-05 -0.06248 0.002536"
        rpy="0 0 0" />
      <mass
        value="0.27473" />
      <inertia
        ixx="0.00029283"
        ixy="4.5586E-07"
        ixz="5.8042E-08"
        iyy="0.00018852"
        iyz="-1.116E-06"
        izz="0.00031238" />
    </inertial>
    <visual>
      <origin
        xyz="0 0 0"
        rpy="0 0 0" />
      <geometry>
        <mesh
          filename="package://g1_description/meshes/Link4_r.STL" />
      </geometry>
      <material
        name="">
        <color
          rgba="0.75294 0.75294 0.75294 1" />
      </material>
    </visual>
    <collision>
      <origin
        xyz="0 0 0"
        rpy="0 0 0" />
      <geometry>
        <mesh
          filename="package://g1_description/meshes/Link4_r.STL" />
      </geometry>
    </collision>
  </link>
  <joint
    name="Joint4_r"
    type="revolute">
    <origin
      xyz="0 0 0"
      rpy="-1.5708 0 -3.1416" />
    <parent
      link="Link3_r" />
    <child
      link="Link4_r" />
    <axis
      xyz="0 0 1" />
    <limit
      lower="-1.48"
      upper="1.48"
      effort="60"
      velocity="3.14" />
  </joint>
  <link
    name="Link5_r">
    <inertial>
      <origin
        xyz="2.6223E-06 -0.00023041 -0.024141"
        rpy="0 0 0" />
      <mass
        value="0.25139" />
      <inertia
        ixx="0.00023516"
        ixy="-6.5868E-09"
        ixz="-1.9428E-08"
        iyy="0.00028807"
        iyz="-1.2108E-05"
        izz="0.00013068" />
    </inertial>
    <visual>
      <origin
        xyz="0 0 0"
        rpy="0 0 0" />
      <geometry>
        <mesh
          filename="package://g1_description/meshes/Link5_r.STL" />
      </geometry>
      <material
        name="">
        <color
          rgba="0.75294 0.75294 0.75294 1" />
      </material>
    </visual>
    <collision>
      <origin
        xyz="0 0 0"
        rpy="0 0 0" />
      <geometry>
        <mesh
          filename="package://g1_description/meshes/Link5_r.STL" />
      </geometry>
    </collision>
  </link>
  <joint
    name="Joint5_r"
    type="revolute">
    <origin
      xyz="0 -0.1975 0"
      rpy="-1.5708 0 3.1416" />
    <parent
      link="Link4_r" />
    <child
      link="Link5_r" />
    <axis
      xyz="0 0 1" />
    <limit
      lower="-3.14"
      upper="3.14"
      effort="30"
      velocity="3.14" />
  </joint>
  <link
    name="Link6_r">
    <inertial>
      <origin
        xyz="5.0382E-06 -0.086696 0.002556"
        rpy="0 0 0" />
      <mass
        value="0.26634" />
      <inertia
        ixx="0.00031434"
        ixy="-1.2113E-09"
        ixz="1.0011E-07"
        iyy="0.00014464"
        iyz="-2.033E-05"
        izz="0.00032449" />
    </inertial>
    <visual>
      <origin
        xyz="0 0 0"
        rpy="0 0 0" />
      <geometry>
        <mesh
          filename="package://g1_description/meshes/Link6_r.STL" />
      </geometry>
      <material
        name="">
        <color
          rgba="0.75294 0.75294 0.75294 1" />
      </material>
    </visual>
    <collision>
      <origin
        xyz="0 0 0"
        rpy="0 0 0" />
      <geometry>
        <mesh
          filename="package://g1_description/meshes/Link6_r.STL" />
      </geometry>
    </collision>
  </link>
  <joint
    name="Joint6_r"
    type="revolute">
    <origin
      xyz="0 0 0"
      rpy="-1.5708 0 0" />
    <parent
      link="Link5_r" />
    <child
      link="Link6_r" />
    <axis
      xyz="0 0 1" />
    <limit
      lower="-1.74"
      upper="1.74"
      effort="30"
      velocity="3.14" />
  </joint>
  <link
    name="Link7_r">
    <inertial>
      <origin
        xyz="-7.5134E-05 -0.00024521 -0.016705"
        rpy="0 0 0" />
      <mass
        value="0.06158" />
      <inertia
        ixx="1.8407E-05"
        ixy="3.4818E-08"
        ixz="-3.2902E-09"
        iyy="1.818E-05"
        iyz="1.1326E-07"
        izz="2.8547E-05" />
    </inertial>
    <visual>
      <origin
        xyz="0 0 0"
        rpy="0 0 0" />
      <geometry>
        <mesh
          filename="package://g1_description/meshes/Link7_r.STL" />
      </geometry>
      <material
        name="">
        <color
          rgba="0.75294 0.75294 0.75294 1" />
      </material>
    </visual>
    <collision>
      <origin
        xyz="0 0 0"
        rpy="0 0 0" />
      <geometry>
        <mesh
          filename="package://g1_description/meshes/Link7_r.STL" />
      </geometry>
    </collision>
  </link>
  <joint
    name="Joint7_r"
    type="revolute">
    <origin
      xyz="0 -0.1805 0"
      rpy="1.5708 0 0" />
    <parent
      link="Link6_r" />
    <child
      link="Link7_r" />
    <axis
      xyz="0 0 1" />
    <limit
      lower="-3.14"
      upper="3.14"
      effort="30"
      velocity="3.14" />
  </joint>
  <link
    name="Link_hand_r">
    <inertial>
      <origin
        xyz="0.0014587 -0.0031343 0.065888"
        rpy="0 0 0" />
      <mass
        value="0.053878" />
      <inertia
        ixx="1.4051E-05"
        ixy="1.9716E-08"
        ixz="4.0724E-07"
        iyy="2.1078E-05"
        iyz="-8.9137E-07"
        izz="1.6258E-05" />
    </inertial>
    <visual>
      <origin
        xyz="0 0 0"
        rpy="0 0 0" />
      <geometry>
        <mesh
          filename="package://g1_description/meshes/Link_hand_r.STL" />
      </geometry>
      <material
        name="">
        <color
          rgba="0.75294 0.75294 0.75294 1" />
      </material>
    </visual>
    <collision>
      <origin
        xyz="0 0 0"
        rpy="0 0 0" />
      <geometry>
        <mesh
          filename="package://g1_description/meshes/Link_hand_r.STL" />
      </geometry>
    </collision>
  </link>
  <joint
    name="Joint_hand_r"
    type="fixed">
    <origin
      xyz="0 0 0"
      rpy="0 0 0.5236" /> <!-- 30度 -->
    <parent
      link="Link7_r" />
    <child
      link="Link_hand_r" />
    <axis
      xyz="0 0 0" />
  </joint>
</robot>